2024-12-10 19:30:49,839 - INFO - Finished! Total sfe time: 9.698361873626709 
2024-12-10 19:30:49,840 - DEBUG - 28,server, Parsed server ram usage: 80696
2024-12-10 19:30:49,840 - DEBUG - 28,client, Parsed client ram usage: 80780
2024-12-10 19:31:06,872 - DEBUG - client all values : ['modprobe cpufreq_stats failedLoaded 0 prior measurements', 'RAPL device for cpu 0', 'RAPL device for cpu 0', 'Devfreq not enabled', 'glob returned GLOB_ABORTED', 'Preparing to take measurements', 'Taking 1 measurement(s) for a duration of 10 second(s) each.', '2024-12-10 19:29:17,637 - tno.mpc.communication.httphandlers - INFO - Serving on 192.168.1.1:61002', '2024-12-10 19:29:17,639 - tno.mpc.communication.httphandlers - ERROR - Message not received.', 'Traceback (most recent call last):', '  File "/home/kamil/.local/lib/python3.9/site-packages/aiohttp/connector.py", line 1061, in _wrap_create_connection', '    sock = await aiohappyeyeballs.start_connection(', '  File "/home/kamil/.local/lib/python3.9/site-packages/aiohappyeyeballs/impl.py", line 103, in start_connection', '    raise first_exception', '  File "/home/kamil/.local/lib/python3.9/site-packages/aiohappyeyeballs/impl.py", line 81, in start_connection', '    sock = await _connect_sock(', '  File "/home/kamil/.local/lib/python3.9/site-packages/aiohappyeyeballs/impl.py", line 165, in _connect_sock', '    await loop.sock_connect(sock, address)', '  File "/usr/lib/python3.9/asyncio/selector_events.py", line 502, in sock_connect', '    return await fut', '  File "/usr/lib/python3.9/asyncio/selector_events.py", line 537, in _sock_connect_cb', "    raise OSError(err, f'Connect call failed {address}')", "ConnectionRefusedError: [Errno 111] Connect call failed ('192.168.1.2', 61001)", '', 'The above exception was the direct cause of the following exception:', '', 'Traceback (most recent call last):', '  File "/home/kamil/.local/lib/python3.9/site-packages/tno/mpc/communication/httphandlers.py", line 193, in _send', '    async with self.session.post(', '  File "/home/kamil/.local/lib/python3.9/site-packages/aiohttp/client.py", line 1355, in __aenter__', '    self._resp: _RetType = await self._coro', '  File "/home/kamil/.local/lib/python3.9/site-packages/aiohttp/client.py", line 659, in _request', '    conn = await self._connector.connect(', '  File "/home/kamil/.local/lib/python3.9/site-packages/aiohttp/connector.py", line 557, in connect', '    proto = await self._create_connection(req, traces, timeout)', '  File "/home/kamil/.local/lib/python3.9/site-packages/aiohttp/connector.py", line 1002, in _create_connection', '    _, proto = await self._create_direct_connection(req, traces, timeout)', '  File "/home/kamil/.local/lib/python3.9/site-packages/aiohttp/connector.py", line 1336, in _create_direct_connection', '    raise last_exc', '  File "/home/kamil/.local/lib/python3.9/site-packages/aiohttp/connector.py", line 1305, in _create_direct_connection', '    transp, proto = await self._wrap_create_connection(', '  File "/home/kamil/.local/lib/python3.9/site-packages/aiohttp/connector.py", line 1076, in _wrap_create_connection', '    raise client_error(req.connection_key, exc) from exc', "aiohttp.client_exceptions.ClientConnectorError: Cannot connect to host 192.168.1.2:61001 ssl:default [Connect call failed ('192.168.1.2', 61001)]", '2024-12-10 19:29:18,653 - tno.mpc.communication.httphandlers - ERROR - Message not received.', 'Traceback (most recent call last):', '  File "/home/kamil/.local/lib/python3.9/site-packages/aiohttp/connector.py", line 1061, in _wrap_create_connection', '    sock = await aiohappyeyeballs.start_connection(', '  File "/home/kamil/.local/lib/python3.9/site-packages/aiohappyeyeballs/impl.py", line 103, in start_connection', '    raise first_exception', '  File "/home/kamil/.local/lib/python3.9/site-packages/aiohappyeyeballs/impl.py", line 81, in start_connection', '    sock = await _connect_sock(', '  File "/home/kamil/.local/lib/python3.9/site-packages/aiohappyeyeballs/impl.py", line 165, in _connect_sock', '    await loop.sock_connect(sock, address)', '  File "/usr/lib/python3.9/asyncio/selector_events.py", line 502, in sock_connect', '    return await fut', '  File "/usr/lib/python3.9/asyncio/selector_events.py", line 537, in _sock_connect_cb', "    raise OSError(err, f'Connect call failed {address}')", "ConnectionRefusedError: [Errno 111] Connect call failed ('192.168.1.2', 61001)", '', 'The above exception was the direct cause of the following exception:', '', 'Traceback (most recent call last):', '  File "/home/kamil/.local/lib/python3.9/site-packages/tno/mpc/communication/httphandlers.py", line 193, in _send', '    async with self.session.post(', '  File "/home/kamil/.local/lib/python3.9/site-packages/aiohttp/client.py", line 1355, in __aenter__', '    self._resp: _RetType = await self._coro', '  File "/home/kamil/.local/lib/python3.9/site-packages/aiohttp/client.py", line 659, in _request', '    conn = await self._connector.connect(', '  File "/home/kamil/.local/lib/python3.9/site-packages/aiohttp/connector.py", line 557, in connect', '    proto = await self._create_connection(req, traces, timeout)', '  File "/home/kamil/.local/lib/python3.9/site-packages/aiohttp/connector.py", line 1002, in _create_connection', '    _, proto = await self._create_direct_connection(req, traces, timeout)', '  File "/home/kamil/.local/lib/python3.9/site-packages/aiohttp/connector.py", line 1336, in _create_direct_connection', '    raise last_exc', '  File "/home/kamil/.local/lib/python3.9/site-packages/aiohttp/connector.py", line 1305, in _create_direct_connection', '    transp, proto = await self._wrap_create_connection(', '  File "/home/kamil/.local/lib/python3.9/site-packages/aiohttp/connector.py", line 1076, in _wrap_create_connection', '    raise client_error(req.connection_key, exc) from exc', "aiohttp.client_exceptions.ClientConnectorError: Cannot connect to host 192.168.1.2:61001 ssl:default [Connect call failed ('192.168.1.2', 61001)]", '2024-12-10 19:29:19,660 - tno.mpc.communication.httphandlers - ERROR - Message not received.', 'Traceback (most recent call last):', '  File "/home/kamil/.local/lib/python3.9/site-packages/aiohttp/connector.py", line 1061, in _wrap_create_connection', '    sock = await aiohappyeyeballs.start_connection(', '  File "/home/kamil/.local/lib/python3.9/site-packages/aiohappyeyeballs/impl.py", line 103, in start_connection', '    raise first_exception', '  File "/home/kamil/.local/lib/python3.9/site-packages/aiohappyeyeballs/impl.py", line 81, in start_connection', '    sock = await _connect_sock(', '  File "/home/kamil/.local/lib/python3.9/site-packages/aiohappyeyeballs/impl.py", line 165, in _connect_sock', '    await loop.sock_connect(sock, address)', '  File "/usr/lib/python3.9/asyncio/selector_events.py", line 502, in sock_connect', '    return await fut', '  File "/usr/lib/python3.9/asyncio/selector_events.py", line 537, in _sock_connect_cb', "    raise OSError(err, f'Connect call failed {address}')", "ConnectionRefusedError: [Errno 111] Connect call failed ('192.168.1.2', 61001)", '', 'The above exception was the direct cause of the following exception:', '', 'Traceback (most recent call last):', '  File "/home/kamil/.local/lib/python3.9/site-packages/tno/mpc/communication/httphandlers.py", line 193, in _send', '    async with self.session.post(', '  File "/home/kamil/.local/lib/python3.9/site-packages/aiohttp/client.py", line 1355, in __aenter__', '    self._resp: _RetType = await self._coro', '  File "/home/kamil/.local/lib/python3.9/site-packages/aiohttp/client.py", line 659, in _request', '    conn = await self._connector.connect(', '  File "/home/kamil/.local/lib/python3.9/site-packages/aiohttp/connector.py", line 557, in connect', '    proto = await self._create_connection(req, traces, timeout)', '  File "/home/kamil/.local/lib/python3.9/site-packages/aiohttp/connector.py", line 1002, in _create_connection', '    _, proto = await self._create_direct_connection(req, traces, timeout)', '  File "/home/kamil/.local/lib/python3.9/site-packages/aiohttp/connector.py", line 1336, in _create_direct_connection', '    raise last_exc', '  File "/home/kamil/.local/lib/python3.9/site-packages/aiohttp/connector.py", line 1305, in _create_direct_connection', '    transp, proto = await self._wrap_create_connection(', '  File "/home/kamil/.local/lib/python3.9/site-packages/aiohttp/connector.py", line 1076, in _wrap_create_connection', '    raise client_error(req.connection_key, exc) from exc', "aiohttp.client_exceptions.ClientConnectorError: Cannot connect to host 192.168.1.2:61001 ssl:default [Connect call failed ('192.168.1.2', 61001)]", '2024-12-10 19:29:20,668 - tno.mpc.communication.httphandlers - ERROR - Message not received.', 'Traceback (most recent call last):', '  File "/home/kamil/.local/lib/python3.9/site-packages/aiohttp/connector.py", line 1061, in _wrap_create_connection', '    sock = await aiohappyeyeballs.start_connection(', '  File "/home/kamil/.local/lib/python3.9/site-packages/aiohappyeyeballs/impl.py", line 103, in start_connection', '    raise first_exception', '  File "/home/kamil/.local/lib/python3.9/site-packages/aiohappyeyeballs/impl.py", line 81, in start_connection', '    sock = await _connect_sock(', '  File "/home/kamil/.local/lib/python3.9/site-packages/aiohappyeyeballs/impl.py", line 165, in _connect_sock', '    await loop.sock_connect(sock, address)', '  File "/usr/lib/python3.9/asyncio/selector_events.py", line 502, in sock_connect', '    return await fut', '  File "/usr/lib/python3.9/asyncio/selector_events.py", line 537, in _sock_connect_cb', "    raise OSError(err, f'Connect call failed {address}')", "ConnectionRefusedError: [Errno 111] Connect call failed ('192.168.1.2', 61001)", '', 'The above exception was the direct cause of the following exception:', '', 'Traceback (most recent call last):', '  File "/home/kamil/.local/lib/python3.9/site-packages/tno/mpc/communication/httphandlers.py", line 193, in _send', '    async with self.session.post(', '  File "/home/kamil/.local/lib/python3.9/site-packages/aiohttp/client.py", line 1355, in __aenter__', '    self._resp: _RetType = await self._coro', '  File "/home/kamil/.local/lib/python3.9/site-packages/aiohttp/client.py", line 659, in _request', '    conn = await self._connector.connect(', '  File "/home/kamil/.local/lib/python3.9/site-packages/aiohttp/connector.py", line 557, in connect', '    proto = await self._create_connection(req, traces, timeout)', '  File "/home/kamil/.local/lib/python3.9/site-packages/aiohttp/connector.py", line 1002, in _create_connection', '    _, proto = await self._create_direct_connection(req, traces, timeout)', '  File "/home/kamil/.local/lib/python3.9/site-packages/aiohttp/connector.py", line 1336, in _create_direct_connection', '    raise last_exc', '  File "/home/kamil/.local/lib/python3.9/site-packages/aiohttp/connector.py", line 1305, in _create_direct_connection', '    transp, proto = await self._wrap_create_connection(', '  File "/home/kamil/.local/lib/python3.9/site-packages/aiohttp/connector.py", line 1076, in _wrap_create_connection', '    raise client_error(req.connection_key, exc) from exc', "aiohttp.client_exceptions.ClientConnectorError: Cannot connect to host 192.168.1.2:61001 ssl:default [Connect call failed ('192.168.1.2', 61001)]", '2024-12-10 19:29:21,715 - tno.mpc.communication.httphandlers - INFO - Received message from 192.168.1.2:61001', '2024-12-10 19:29:21,743 - tno.mpc.communication.httphandlers - INFO - Received message from 192.168.1.2:61001', '2024-12-10 19:29:21,805 - tno.mpc.communication.httphandlers - INFO - Received message from 192.168.1.2:61001', '2024-12-10 19:29:21,840 - tno.mpc.communication.httphandlers - INFO - Received message from 192.168.1.2:61001', 'TP is  0.001', '2024-12-10 19:29:21,853 - tno.mpc.communication.httphandlers - INFO - Received message from 192.168.1.2:61001', '2024-12-10 19:29:21,868 - tno.mpc.communication.httphandlers - INFO - HTTPServer: Shutting down server task', '2024-12-10 19:29:21,869 - tno.mpc.communication.httphandlers - INFO - Server 192.168.1.1:61002 shutdown', 'Total bytes received: 1930', 'Total messages received: 5', '2024-12-10 19:29:21,871 - tno.mpc.communication.httphandlers - INFO - Client 192.168.1.2:61001 shutdown', 'Total bytes sent: 766', 'Total messages sent: 5', '2024-12-10 19:29:21,871 - tno.mpc.communication.pool - INFO - Pool shutdown.', 'Total bytes sent: 766', 'Total messages sent: 5', 'Total bytes received: 1930', 'Total messages received: 5', '\tCommand being timed: "python3.9 server_energy.py 1 28"', '\tUser time (seconds): 3.47', '\tSystem time (seconds): 0.36', '\tPercent of CPU this job got: 48%', '\tElapsed (wall clock) time (h:mm:ss or m:ss): 0:07.98', '\tAverage shared text size (kbytes): 0', '\tAverage unshared data size (kbytes): 0', '\tAverage stack size (kbytes): 0', '\tAverage total size (kbytes): 0', '\tMaximum resident set size (kbytes): 81088', '\tAverage resident set size (kbytes): 0', '\tMajor (requiring I/O) page faults: 0', '\tMinor (reclaiming a frame) page faults: 16103', '\tVoluntary context switches: 75', '\tInvoluntary context switches: 308', '\tSwaps: 0', '\tFile system inputs: 0', '\tFile system outputs: 0', '\tSocket messages sent: 0', '\tSocket messages received: 0', '\tSignals delivered: 0', '\tPage size (bytes): 4096', '\tExit status: 0', 'PowerTOP outputing using base filename log/powertop_10mbits_2024-12-10_19-30-40.csv']
2024-12-10 19:31:06,873 - DEBUG - server all values : ['modprobe cpufreq_stats failedLoaded 0 prior measurements', 'RAPL device for cpu 0', 'RAPL device for cpu 0', 'Devfreq not enabled', 'glob returned GLOB_ABORTED', 'Preparing to take measurements', 'Taking 1 measurement(s) for a duration of 10 second(s) each.', '2024-12-10 19:30:10,695 - tno.mpc.communication.httphandlers - INFO - Serving on 192.168.1.2:61001', '2024-12-10 19:30:11,261 - tno.mpc.communication.httphandlers - INFO - Received message from 192.168.1.1:61002', '2024-12-10 19:30:11,345 - tno.mpc.communication.httphandlers - INFO - Received message from 192.168.1.1:61002', '2024-12-10 19:30:11,371 - tno.mpc.communication.httphandlers - INFO - Received message from 192.168.1.1:61002', '2024-12-10 19:30:11,407 - tno.mpc.communication.httphandlers - INFO - Received message from 192.168.1.1:61002', 'TP is  0.001', '2024-12-10 19:30:11,441 - tno.mpc.communication.httphandlers - INFO - Received message from 192.168.1.1:61002', '2024-12-10 19:30:11,446 - tno.mpc.communication.httphandlers - INFO - HTTPServer: Shutting down server task', '2024-12-10 19:30:11,447 - tno.mpc.communication.httphandlers - INFO - Server 192.168.1.2:61001 shutdown', 'Total bytes received: 766', 'Total messages received: 5', '2024-12-10 19:30:11,450 - tno.mpc.communication.httphandlers - INFO - Client 192.168.1.1:61002 shutdown', 'Total bytes sent: 1930', 'Total messages sent: 5', '2024-12-10 19:30:11,451 - tno.mpc.communication.pool - INFO - Pool shutdown.', 'Total bytes sent: 1930', 'Total messages sent: 5', 'Total bytes received: 766', 'Total messages received: 5', '\tCommand being timed: "python3.9 server_energy.py 0 28"', '\tUser time (seconds): 6.74', '\tSystem time (seconds): 0.75', '\tPercent of CPU this job got: 92%', '\tElapsed (wall clock) time (h:mm:ss or m:ss): 0:08.10', '\tAverage shared text size (kbytes): 0', '\tAverage unshared data size (kbytes): 0', '\tAverage stack size (kbytes): 0', '\tAverage total size (kbytes): 0', '\tMaximum resident set size (kbytes): 79812', '\tAverage resident set size (kbytes): 0', '\tMajor (requiring I/O) page faults: 0', '\tMinor (reclaiming a frame) page faults: 15952', '\tVoluntary context switches: 63', '\tInvoluntary context switches: 133', '\tSwaps: 0', '\tFile system inputs: 0', '\tFile system outputs: 0', '\tSocket messages sent: 0', '\tSocket messages received: 0', '\tSignals delivered: 0', '\tPage size (bytes): 4096', '\tExit status: 0', 'PowerTOP outputing using base filename log/powertop_10mbits_2024-12-10_19-30-40.csv']
2024-12-10 19:31:07,650 - DEBUG - All values from powertop for client: 1       199 mW  
35     1.05 mW  
54      359 uW  
Name: 7, dtype: object
2024-12-10 19:31:07,650 - DEBUG - Energy client: 0.83370144
2024-12-10 19:31:08,941 - DEBUG - All values from powertop for server: 1       602 mW  
27     1.21 mW  
39      516 uW  
Name: 7, dtype: object
2024-12-10 19:31:08,941 - DEBUG - Energy server: 4.49172144
