2024-12-10 20:02:59,935 - INFO - Finished! Total sfe time: 10.511291742324829 
2024-12-10 20:02:59,936 - DEBUG - 92,server, Parsed server ram usage: 80328
2024-12-10 20:02:59,936 - DEBUG - 92,client, Parsed client ram usage: 81096
2024-12-10 20:03:18,081 - DEBUG - client all values : ['modprobe cpufreq_stats failedLoaded 0 prior measurements', 'RAPL device for cpu 0', 'RAPL device for cpu 0', 'Devfreq not enabled', 'glob returned GLOB_ABORTED', 'Preparing to take measurements', 'Taking 1 measurement(s) for a duration of 11 second(s) each.', '2024-12-10 20:01:27,994 - tno.mpc.communication.httphandlers - INFO - Serving on 192.168.1.1:61002', '2024-12-10 20:01:27,997 - tno.mpc.communication.httphandlers - ERROR - Message not received.', 'Traceback (most recent call last):', '  File "/home/kamil/.local/lib/python3.9/site-packages/aiohttp/connector.py", line 1061, in _wrap_create_connection', '    sock = await aiohappyeyeballs.start_connection(', '  File "/home/kamil/.local/lib/python3.9/site-packages/aiohappyeyeballs/impl.py", line 103, in start_connection', '    raise first_exception', '  File "/home/kamil/.local/lib/python3.9/site-packages/aiohappyeyeballs/impl.py", line 81, in start_connection', '    sock = await _connect_sock(', '  File "/home/kamil/.local/lib/python3.9/site-packages/aiohappyeyeballs/impl.py", line 165, in _connect_sock', '    await loop.sock_connect(sock, address)', '  File "/usr/lib/python3.9/asyncio/selector_events.py", line 502, in sock_connect', '    return await fut', '  File "/usr/lib/python3.9/asyncio/selector_events.py", line 537, in _sock_connect_cb', "    raise OSError(err, f'Connect call failed {address}')", "ConnectionRefusedError: [Errno 111] Connect call failed ('192.168.1.2', 61001)", '', 'The above exception was the direct cause of the following exception:', '', 'Traceback (most recent call last):', '  File "/home/kamil/.local/lib/python3.9/site-packages/tno/mpc/communication/httphandlers.py", line 193, in _send', '    async with self.session.post(', '  File "/home/kamil/.local/lib/python3.9/site-packages/aiohttp/client.py", line 1355, in __aenter__', '    self._resp: _RetType = await self._coro', '  File "/home/kamil/.local/lib/python3.9/site-packages/aiohttp/client.py", line 659, in _request', '    conn = await self._connector.connect(', '  File "/home/kamil/.local/lib/python3.9/site-packages/aiohttp/connector.py", line 557, in connect', '    proto = await self._create_connection(req, traces, timeout)', '  File "/home/kamil/.local/lib/python3.9/site-packages/aiohttp/connector.py", line 1002, in _create_connection', '    _, proto = await self._create_direct_connection(req, traces, timeout)', '  File "/home/kamil/.local/lib/python3.9/site-packages/aiohttp/connector.py", line 1336, in _create_direct_connection', '    raise last_exc', '  File "/home/kamil/.local/lib/python3.9/site-packages/aiohttp/connector.py", line 1305, in _create_direct_connection', '    transp, proto = await self._wrap_create_connection(', '  File "/home/kamil/.local/lib/python3.9/site-packages/aiohttp/connector.py", line 1076, in _wrap_create_connection', '    raise client_error(req.connection_key, exc) from exc', "aiohttp.client_exceptions.ClientConnectorError: Cannot connect to host 192.168.1.2:61001 ssl:default [Connect call failed ('192.168.1.2', 61001)]", '2024-12-10 20:01:29,023 - tno.mpc.communication.httphandlers - ERROR - Message not received.', 'Traceback (most recent call last):', '  File "/home/kamil/.local/lib/python3.9/site-packages/aiohttp/connector.py", line 1061, in _wrap_create_connection', '    sock = await aiohappyeyeballs.start_connection(', '  File "/home/kamil/.local/lib/python3.9/site-packages/aiohappyeyeballs/impl.py", line 103, in start_connection', '    raise first_exception', '  File "/home/kamil/.local/lib/python3.9/site-packages/aiohappyeyeballs/impl.py", line 81, in start_connection', '    sock = await _connect_sock(', '  File "/home/kamil/.local/lib/python3.9/site-packages/aiohappyeyeballs/impl.py", line 165, in _connect_sock', '    await loop.sock_connect(sock, address)', '  File "/usr/lib/python3.9/asyncio/selector_events.py", line 502, in sock_connect', '    return await fut', '  File "/usr/lib/python3.9/asyncio/selector_events.py", line 537, in _sock_connect_cb', "    raise OSError(err, f'Connect call failed {address}')", "ConnectionRefusedError: [Errno 111] Connect call failed ('192.168.1.2', 61001)", '', 'The above exception was the direct cause of the following exception:', '', 'Traceback (most recent call last):', '  File "/home/kamil/.local/lib/python3.9/site-packages/tno/mpc/communication/httphandlers.py", line 193, in _send', '    async with self.session.post(', '  File "/home/kamil/.local/lib/python3.9/site-packages/aiohttp/client.py", line 1355, in __aenter__', '    self._resp: _RetType = await self._coro', '  File "/home/kamil/.local/lib/python3.9/site-packages/aiohttp/client.py", line 659, in _request', '    conn = await self._connector.connect(', '  File "/home/kamil/.local/lib/python3.9/site-packages/aiohttp/connector.py", line 557, in connect', '    proto = await self._create_connection(req, traces, timeout)', '  File "/home/kamil/.local/lib/python3.9/site-packages/aiohttp/connector.py", line 1002, in _create_connection', '    _, proto = await self._create_direct_connection(req, traces, timeout)', '  File "/home/kamil/.local/lib/python3.9/site-packages/aiohttp/connector.py", line 1336, in _create_direct_connection', '    raise last_exc', '  File "/home/kamil/.local/lib/python3.9/site-packages/aiohttp/connector.py", line 1305, in _create_direct_connection', '    transp, proto = await self._wrap_create_connection(', '  File "/home/kamil/.local/lib/python3.9/site-packages/aiohttp/connector.py", line 1076, in _wrap_create_connection', '    raise client_error(req.connection_key, exc) from exc', "aiohttp.client_exceptions.ClientConnectorError: Cannot connect to host 192.168.1.2:61001 ssl:default [Connect call failed ('192.168.1.2', 61001)]", '2024-12-10 20:01:30,033 - tno.mpc.communication.httphandlers - ERROR - Message not received.', 'Traceback (most recent call last):', '  File "/home/kamil/.local/lib/python3.9/site-packages/aiohttp/connector.py", line 1061, in _wrap_create_connection', '    sock = await aiohappyeyeballs.start_connection(', '  File "/home/kamil/.local/lib/python3.9/site-packages/aiohappyeyeballs/impl.py", line 103, in start_connection', '    raise first_exception', '  File "/home/kamil/.local/lib/python3.9/site-packages/aiohappyeyeballs/impl.py", line 81, in start_connection', '    sock = await _connect_sock(', '  File "/home/kamil/.local/lib/python3.9/site-packages/aiohappyeyeballs/impl.py", line 165, in _connect_sock', '    await loop.sock_connect(sock, address)', '  File "/usr/lib/python3.9/asyncio/selector_events.py", line 502, in sock_connect', '    return await fut', '  File "/usr/lib/python3.9/asyncio/selector_events.py", line 537, in _sock_connect_cb', "    raise OSError(err, f'Connect call failed {address}')", "ConnectionRefusedError: [Errno 111] Connect call failed ('192.168.1.2', 61001)", '', 'The above exception was the direct cause of the following exception:', '', 'Traceback (most recent call last):', '  File "/home/kamil/.local/lib/python3.9/site-packages/tno/mpc/communication/httphandlers.py", line 193, in _send', '    async with self.session.post(', '  File "/home/kamil/.local/lib/python3.9/site-packages/aiohttp/client.py", line 1355, in __aenter__', '    self._resp: _RetType = await self._coro', '  File "/home/kamil/.local/lib/python3.9/site-packages/aiohttp/client.py", line 659, in _request', '    conn = await self._connector.connect(', '  File "/home/kamil/.local/lib/python3.9/site-packages/aiohttp/connector.py", line 557, in connect', '    proto = await self._create_connection(req, traces, timeout)', '  File "/home/kamil/.local/lib/python3.9/site-packages/aiohttp/connector.py", line 1002, in _create_connection', '    _, proto = await self._create_direct_connection(req, traces, timeout)', '  File "/home/kamil/.local/lib/python3.9/site-packages/aiohttp/connector.py", line 1336, in _create_direct_connection', '    raise last_exc', '  File "/home/kamil/.local/lib/python3.9/site-packages/aiohttp/connector.py", line 1305, in _create_direct_connection', '    transp, proto = await self._wrap_create_connection(', '  File "/home/kamil/.local/lib/python3.9/site-packages/aiohttp/connector.py", line 1076, in _wrap_create_connection', '    raise client_error(req.connection_key, exc) from exc', "aiohttp.client_exceptions.ClientConnectorError: Cannot connect to host 192.168.1.2:61001 ssl:default [Connect call failed ('192.168.1.2', 61001)]", '2024-12-10 20:01:31,042 - tno.mpc.communication.httphandlers - ERROR - Message not received.', 'Traceback (most recent call last):', '  File "/home/kamil/.local/lib/python3.9/site-packages/aiohttp/connector.py", line 1061, in _wrap_create_connection', '    sock = await aiohappyeyeballs.start_connection(', '  File "/home/kamil/.local/lib/python3.9/site-packages/aiohappyeyeballs/impl.py", line 103, in start_connection', '    raise first_exception', '  File "/home/kamil/.local/lib/python3.9/site-packages/aiohappyeyeballs/impl.py", line 81, in start_connection', '    sock = await _connect_sock(', '  File "/home/kamil/.local/lib/python3.9/site-packages/aiohappyeyeballs/impl.py", line 165, in _connect_sock', '    await loop.sock_connect(sock, address)', '  File "/usr/lib/python3.9/asyncio/selector_events.py", line 502, in sock_connect', '    return await fut', '  File "/usr/lib/python3.9/asyncio/selector_events.py", line 537, in _sock_connect_cb', "    raise OSError(err, f'Connect call failed {address}')", "ConnectionRefusedError: [Errno 111] Connect call failed ('192.168.1.2', 61001)", '', 'The above exception was the direct cause of the following exception:', '', 'Traceback (most recent call last):', '  File "/home/kamil/.local/lib/python3.9/site-packages/tno/mpc/communication/httphandlers.py", line 193, in _send', '    async with self.session.post(', '  File "/home/kamil/.local/lib/python3.9/site-packages/aiohttp/client.py", line 1355, in __aenter__', '    self._resp: _RetType = await self._coro', '  File "/home/kamil/.local/lib/python3.9/site-packages/aiohttp/client.py", line 659, in _request', '    conn = await self._connector.connect(', '  File "/home/kamil/.local/lib/python3.9/site-packages/aiohttp/connector.py", line 557, in connect', '    proto = await self._create_connection(req, traces, timeout)', '  File "/home/kamil/.local/lib/python3.9/site-packages/aiohttp/connector.py", line 1002, in _create_connection', '    _, proto = await self._create_direct_connection(req, traces, timeout)', '  File "/home/kamil/.local/lib/python3.9/site-packages/aiohttp/connector.py", line 1336, in _create_direct_connection', '    raise last_exc', '  File "/home/kamil/.local/lib/python3.9/site-packages/aiohttp/connector.py", line 1305, in _create_direct_connection', '    transp, proto = await self._wrap_create_connection(', '  File "/home/kamil/.local/lib/python3.9/site-packages/aiohttp/connector.py", line 1076, in _wrap_create_connection', '    raise client_error(req.connection_key, exc) from exc', "aiohttp.client_exceptions.ClientConnectorError: Cannot connect to host 192.168.1.2:61001 ssl:default [Connect call failed ('192.168.1.2', 61001)]", '2024-12-10 20:01:32,091 - tno.mpc.communication.httphandlers - INFO - Received message from 192.168.1.2:61001', '2024-12-10 20:01:32,119 - tno.mpc.communication.httphandlers - INFO - Received message from 192.168.1.2:61001', '2024-12-10 20:01:32,179 - tno.mpc.communication.httphandlers - INFO - Received message from 192.168.1.2:61001', '2024-12-10 20:01:32,217 - tno.mpc.communication.httphandlers - INFO - Received message from 192.168.1.2:61001', 'TP is  0.001', '2024-12-10 20:01:32,230 - tno.mpc.communication.httphandlers - INFO - Received message from 192.168.1.2:61001', '2024-12-10 20:01:32,245 - tno.mpc.communication.httphandlers - INFO - HTTPServer: Shutting down server task', '2024-12-10 20:01:32,246 - tno.mpc.communication.httphandlers - INFO - Server 192.168.1.1:61002 shutdown', 'Total bytes received: 1930', 'Total messages received: 5', '2024-12-10 20:01:32,248 - tno.mpc.communication.httphandlers - INFO - Client 192.168.1.2:61001 shutdown', 'Total bytes sent: 766', 'Total messages sent: 5', '2024-12-10 20:01:32,248 - tno.mpc.communication.pool - INFO - Pool shutdown.', 'Total bytes sent: 766', 'Total messages sent: 5', 'Total bytes received: 1930', 'Total messages received: 5', '\tCommand being timed: "python3.9 server_energy.py 1 92"', '\tUser time (seconds): 3.64', '\tSystem time (seconds): 0.40', '\tPercent of CPU this job got: 49%', '\tElapsed (wall clock) time (h:mm:ss or m:ss): 0:08.19', '\tAverage shared text size (kbytes): 0', '\tAverage unshared data size (kbytes): 0', '\tAverage stack size (kbytes): 0', '\tAverage total size (kbytes): 0', '\tMaximum resident set size (kbytes): 80316', '\tAverage resident set size (kbytes): 0', '\tMajor (requiring I/O) page faults: 0', '\tMinor (reclaiming a frame) page faults: 16090', '\tVoluntary context switches: 75', '\tInvoluntary context switches: 323', '\tSwaps: 0', '\tFile system inputs: 0', '\tFile system outputs: 0', '\tSocket messages sent: 0', '\tSocket messages received: 0', '\tSignals delivered: 0', '\tPage size (bytes): 4096', '\tExit status: 0', 'PowerTOP outputing using base filename log/powertop_10mbits_2024-12-10_20-02-49.csv']
2024-12-10 20:03:18,081 - DEBUG - server all values : ['modprobe cpufreq_stats failedLoaded 0 prior measurements', 'RAPL device for cpu 0', 'RAPL device for cpu 0', 'Devfreq not enabled', 'glob returned GLOB_ABORTED', 'Preparing to take measurements', 'Taking 1 measurement(s) for a duration of 11 second(s) each.', '2024-12-10 20:02:20,898 - tno.mpc.communication.httphandlers - INFO - Serving on 192.168.1.2:61001', '2024-12-10 20:02:21,645 - tno.mpc.communication.httphandlers - INFO - Received message from 192.168.1.1:61002', '2024-12-10 20:02:21,729 - tno.mpc.communication.httphandlers - INFO - Received message from 192.168.1.1:61002', '2024-12-10 20:02:21,757 - tno.mpc.communication.httphandlers - INFO - Received message from 192.168.1.1:61002', '2024-12-10 20:02:21,792 - tno.mpc.communication.httphandlers - INFO - Received message from 192.168.1.1:61002', 'TP is  0.001', '2024-12-10 20:02:21,826 - tno.mpc.communication.httphandlers - INFO - Received message from 192.168.1.1:61002', '2024-12-10 20:02:21,832 - tno.mpc.communication.httphandlers - INFO - HTTPServer: Shutting down server task', '2024-12-10 20:02:21,834 - tno.mpc.communication.httphandlers - INFO - Server 192.168.1.2:61001 shutdown', 'Total bytes received: 766', 'Total messages received: 5', '2024-12-10 20:02:21,838 - tno.mpc.communication.httphandlers - INFO - Client 192.168.1.1:61002 shutdown', 'Total bytes sent: 1930', 'Total messages sent: 5', '2024-12-10 20:02:21,840 - tno.mpc.communication.pool - INFO - Pool shutdown.', 'Total bytes sent: 1930', 'Total messages sent: 5', 'Total bytes received: 766', 'Total messages received: 5', '\tCommand being timed: "python3.9 server_energy.py 0 92"', '\tUser time (seconds): 6.63', '\tSystem time (seconds): 0.85', '\tPercent of CPU this job got: 90%', '\tElapsed (wall clock) time (h:mm:ss or m:ss): 0:08.28', '\tAverage shared text size (kbytes): 0', '\tAverage unshared data size (kbytes): 0', '\tAverage stack size (kbytes): 0', '\tAverage total size (kbytes): 0', '\tMaximum resident set size (kbytes): 79860', '\tAverage resident set size (kbytes): 0', '\tMajor (requiring I/O) page faults: 0', '\tMinor (reclaiming a frame) page faults: 15949', '\tVoluntary context switches: 50', '\tInvoluntary context switches: 207', '\tSwaps: 0', '\tFile system inputs: 0', '\tFile system outputs: 0', '\tSocket messages sent: 0', '\tSocket messages received: 0', '\tSignals delivered: 0', '\tPage size (bytes): 4096', '\tExit status: 0', 'PowerTOP outputing using base filename log/powertop_10mbits_2024-12-10_20-02-49.csv']
2024-12-10 20:03:18,875 - DEBUG - All values from powertop for client: 1       193 mW  
35      974 uW  
48      387 uW  
Name: 7, dtype: object
2024-12-10 20:03:18,875 - DEBUG - Energy client: 0.8415831300000001
2024-12-10 20:03:20,326 - DEBUG - All values from powertop for server: 1       563 mW  
27     1.27 mW  
Name: 7, dtype: object
2024-12-10 20:03:20,326 - DEBUG - Energy server: 4.1981688
